LOB.Tests/samples/Orders01.txt
ADD	1	B	1	109.60
ADD	2	B	1	109.60
ADD	3	B	1	109.61
CANCEL	3
CANCEL	1
ADD	4	B	1	109.59
ADD	5	B	1	109.50
ADD	6	B	1	109.59
ADD	7	B	1	109.58
ADD	8	B	1	109.57
CANCEL	2
ADD	9	B	1	109.56
CANCEL	7
CANCEL	5
ADD	10	B	1	109.55
CANCEL	6
CANCEL	9
CANCEL	10
CANCEL	4
CANCEL	8
