LOB.Tests/samples/Orders02.txt
ADD	1	B	2	109.60
ADD	2	B	1	109.60
ADD	3	B	2	109.61
FILL	3	B	2
PARTIAL	1	B	1
FILL	1	B	1
FILL	2	B	1
ADD	4	B	1	109.59
ADD	5	B	1	109.50
ADD	6	B	1	109.59
ADD	7	B	1	109.58
ADD	8	B	1	109.57
ADD	9	B	1	109.56
FILL	4	B	1
FILL	6	B	1
ADD	10	B	1	109.55
FILL	7	B	1
FILL	8	B	1
FILL	9	B	1
FILL	10	B	1
FILL	5	B	1
